<?xml version="1.0"?>
<robot name="Ned2" xmlns:xacro="http://ros.org/wiki/xacro">
  <link name="base_link">
    <visual>
      <origin xyz="0.09 0.09 0.003" rpy="-3.141589 0 0"/>
      <geometry>
        <cylinder radius="0.02" length="0.006"/>
      </geometry>
    </visual>
    <collision>
      <origin xyz="0.09 0.09 0.003" rpy="-3.141589 0 0"/>
      <geometry>
        <cylinder radius="0.02" length="0.006"/>
      </geometry>
    </collision>
    <visual>
      <origin xyz="-0.09 0.09 0.003" rpy="-3.141589 0 0"/>
      <geometry>
        <cylinder radius="0.02" length="0.006"/>
      </geometry>
    </visual>
    <collision>
      <origin xyz="-0.09 0.09 0.003" rpy="-3.141589 0 0"/>
      <geometry>
        <cylinder radius="0.02" length="0.006"/>
      </geometry>
    </collision>
    <visual>
      <origin xyz="0.09 -0.09 0.003" rpy="-3.141589 0 0"/>
      <geometry>
        <cylinder radius="0.02" length="0.006"/>
      </geometry>
    </visual>
    <collision>
      <origin xyz="0.09 -0.09 0.003" rpy="-3.141589 0 0"/>
      <geometry>
        <cylinder radius="0.02" length="0.006"/>
      </geometry>
    </collision>
    <visual>
      <origin xyz="-0.09 -0.09 0.003" rpy="-3.141589 0 0"/>
      <geometry>
        <cylinder radius="0.02" length="0.006"/>
      </geometry>
    </visual>
    <collision>
      <origin xyz="-0.09 -0.09 0.003" rpy="-3.141589 0 0"/>
      <geometry>
        <cylinder radius="0.02" length="0.006"/>
      </geometry>
    </collision>
    <visual>
      <origin xyz="0.09 0.09 0.008" rpy="-3.141589 0 0"/>
      <geometry>
        <cylinder radius="0.012" length="0.004"/>
      </geometry>
    </visual>
    <collision>
      <origin xyz="0.09 0.09 0.008" rpy="-3.141589 0 0"/>
      <geometry>
        <cylinder radius="0.012" length="0.004"/>
      </geometry>
    </collision>
    <visual>
      <origin xyz="-0.09 0.09 0.008" rpy="-3.141589 0 0"/>
      <geometry>
        <cylinder radius="0.012" length="0.004"/>
      </geometry>
    </visual>
    <collision>
      <origin xyz="-0.09 0.09 0.008" rpy="-3.141589 0 0"/>
      <geometry>
        <cylinder radius="0.012" length="0.004"/>
      </geometry>
    </collision>
    <visual>
      <origin xyz="0.09 -0.09 0.008" rpy="-3.141589 0 0"/>
      <geometry>
        <cylinder radius="0.012" length="0.004"/>
      </geometry>
    </visual>
    <collision>
      <origin xyz="0.09 -0.09 0.008" rpy="-3.141589 0 0"/>
      <geometry>
        <cylinder radius="0.012" length="0.004"/>
      </geometry>
    </collision>
    <visual>
      <origin xyz="-0.09 -0.09 0.008" rpy="-3.141589 0 0"/>
      <geometry>
        <cylinder radius="0.012" length="0.004"/>
      </geometry>
    </visual>
    <collision>
      <origin xyz="-0.09 -0.09 0.008" rpy="-3.141589 0 0"/>
      <geometry>
        <cylinder radius="0.012" length="0.004"/>
      </geometry>
    </collision>
    <visual>
      <origin xyz="0 0 0.012" rpy="0 0 0"/>
      <geometry>
        <box size="0.2 0.2 0.004"/>
      </geometry>
    </visual>
    <collision>
      <origin xyz="0 0 0.012" rpy="0 0 0"/>
      <geometry>
        <box size="0.2 0.2 0.004"/>
      </geometry>
    </collision>
    <visual>
      <origin xyz="0 -0.0455 0.052" rpy="0 0 0"/>
      <geometry>
        <box size="0.136 0.091 0.076"/>
      </geometry>
    </visual>
    <collision>
      <origin xyz="0 -0.0455 0.052" rpy="0 0 0"/>
      <geometry>
        <box size="0.136 0.091 0.076"/>
      </geometry>
    </collision>
    <visual>
      <origin xyz="0 0.04425 0.052" rpy="0 0 0"/>
      <geometry>
        <box size="0.099 0.0885 0.076"/>
      </geometry>
    </visual>
    <collision>
      <origin xyz="0 0.04425 0.052" rpy="0 0 0"/>
      <geometry>
        <box size="0.099 0.0885 0.076"/>
      </geometry>
    </collision>
    <visual>
      <origin xyz="0.0485 0.0485 0.052" rpy="-3.141589 0 0"/>
      <geometry>
        <cylinder radius="0.04" length="0.076"/>
      </geometry>
    </visual>
    <collision>
      <origin xyz="0.0485 0.0485 0.052" rpy="-3.141589 0 0"/>
      <geometry>
        <cylinder radius="0.04" length="0.076"/>
      </geometry>
    </collision>
    <visual>
      <origin xyz="-0.0485 0.0485 0.052" rpy="-3.141589 0 0"/>
      <geometry>
        <cylinder radius="0.04" length="0.076"/>
      </geometry>
    </visual>
    <collision>
      <origin xyz="-0.0485 0.0485 0.052" rpy="-3.141589 0 0"/>
      <geometry>
        <cylinder radius="0.04" length="0.076"/>
      </geometry>
    </collision>
    <visual>
      <origin xyz="0.068 -0.071 0.052" rpy="-3.141589 0 0"/>
      <geometry>
        <cylinder radius="0.02" length="0.076"/>
      </geometry>
    </visual>
    <collision>
      <origin xyz="0.068 -0.071 0.052" rpy="-3.141589 0 0"/>
      <geometry>
        <cylinder radius="0.02" length="0.076"/>
      </geometry>
    </collision>
    <visual>
      <origin xyz="-0.068 -0.071 0.052" rpy="-3.141589 0 0"/>
      <geometry>
        <cylinder radius="0.02" length="0.076"/>
      </geometry>
    </visual>
    <collision>
      <origin xyz="-0.068 -0.071 0.052" rpy="-3.141589 0 0"/>
      <geometry>
        <cylinder radius="0.02" length="0.076"/>
      </geometry>
    </collision>
    <visual>
      <origin xyz="0 -0.0095 0.052" rpy="0 0 0"/>
      <geometry>
        <box size="0.176 0.1195 0.076"/>
      </geometry>
    </visual>
    <collision>
      <origin xyz="0 -0.0095 0.052" rpy="0 0 0"/>
      <geometry>
        <box size="0.176 0.1195 0.076"/>
      </geometry>
    </collision>
    <visual>
      <origin xyz="0 0 0.0975" rpy="-3.141589 0 0"/>
      <geometry>
        <cylinder radius="0.074" length="0.015"/>
      </geometry>
    </visual>
    <collision>
      <origin xyz="0 0 0.0975" rpy="-3.141589 0 0"/>
      <geometry>
        <cylinder radius="0.074" length="0.015"/>
      </geometry>
    </collision>
  </link>
  <joint name="joint_1" type="revolute">
    <parent link="base_link"/>
    <child link="shoulder_link"/>
    <axis xyz="0 0 1"/>
    <limit effort="10000" lower="-2.8" upper="2.8" velocity="10"/>
    <origin xyz="0 0 0.1065" rpy="0 0 0"/>
  </joint>
  <link name="shoulder_link">
  </link>
  <joint name="joint_2" type="revolute">
    <parent link="shoulder_link"/>
    <child link="arm_link"/>
    <axis xyz="0 0 1"/>
    <limit effort="10000" lower="-0.8" upper="0.8" velocity="10"/>
    <origin xyz="0 0 0.065" rpy="-0.000704 -1.57 0.000704"/>
  </joint>
  <link name="arm_link">
    <visual>
      <origin xyz="0.08 0 0" rpy="1.570796 0 -1.57"/>
      <geometry>
        <cylinder radius="0.02" length="0.07"/>
      </geometry>
    </visual>
    <collision>
      <origin xyz="0.08 0 0" rpy="1.570796 0 -1.57"/>
      <geometry>
        <cylinder radius="0.02" length="0.07"/>
      </geometry>
    </collision>
  </link>
  <joint name="joint_3" type="revolute">
    <parent link="arm_link"/>
    <child link="elbow_link"/>
    <axis xyz="0 0 1"/>
    <limit effort="10000" lower="-1.5" upper="1.3" velocity="10"/>
    <origin xyz="0.221 0.012 0" rpy="0 0 0.000001"/>
  </joint>
  <link name="elbow_link">
  </link>
  <joint name="joint_4" type="revolute">
    <parent link="elbow_link"/>
    <child link="forearm_link"/>
    <axis xyz="-0.000001 0 1"/>
    <limit effort="10000" lower="-2" upper="2" velocity="10"/>
    <origin xyz="0.032 0.042 0" rpy="-1.568656 -1.569999 -0.001344"/>
  </joint>
  <link name="forearm_link">
    <visual>
      <origin xyz="0 0 0.08" rpy="-3.141589 0 0"/>
      <geometry>
        <cylinder radius="0.02" length="0.07"/>
      </geometry>
    </visual>
    <collision>
      <origin xyz="0 0 0.08" rpy="-3.141589 0 0"/>
      <geometry>
        <cylinder radius="0.02" length="0.07"/>
      </geometry>
    </collision>
  </link>
  <joint name="joint_5" type="revolute">
    <parent link="forearm_link"/>
    <child link="wrist_link"/>
    <axis xyz="0.000001 0 1"/>
    <limit effort="10000" lower="-1.5" upper="1.5" velocity="10"/>
    <origin xyz="0 0 0.188" rpy="-1.570187 -1.57 1.570187"/>
  </joint>
  <link name="wrist_link">
  </link>
  <joint name="joint_6" type="revolute">
    <parent link="wrist_link"/>
    <child link="hand_link"/>
    <axis xyz="0 0 1"/>
    <limit effort="10000" lower="-2.5" upper="2.5" velocity="10"/>
    <origin xyz="0.0197 0.00925 0" rpy="0.000001 1.57 0.000001"/>
  </joint>
  <link name="hand_link">
    <visual>
      <origin xyz="0 0 0.011" rpy="-3.141589 0 0"/>
      <geometry>
        <cylinder radius="0.0155" length="0.02"/>
      </geometry>
    </visual>
    <collision>
      <origin xyz="0 0 0.011" rpy="-3.141589 0 0"/>
      <geometry>
        <cylinder radius="0.0155" length="0.02"/>
      </geometry>
    </collision>
    <visual>
      <origin xyz="0 0 -0.001" rpy="-3.141589 0 0"/>
      <geometry>
        <cylinder radius="0.0083" length="0.001"/>
      </geometry>
    </visual>
    <collision>
      <origin xyz="0 0 -0.001" rpy="-3.141589 0 0"/>
      <geometry>
        <cylinder radius="0.0083" length="0.001"/>
      </geometry>
    </collision>
    <visual>
      <origin xyz="0 0 -0.003" rpy="-3.141589 0 0"/>
      <geometry>
        <cylinder radius="0.0066" length="0.002"/>
      </geometry>
    </visual>
    <collision>
      <origin xyz="0 0 -0.003" rpy="-3.141589 0 0"/>
      <geometry>
        <cylinder radius="0.0066" length="0.002"/>
      </geometry>
    </collision>
  </link>
  <link name="base_gripper_1">
  </link>
  <joint name="hand_link_base_gripper_1_joint" type="fixed">
    <parent link="hand_link"/>
    <child link="base_gripper_1"/>
    <origin xyz="0 0 0.0215" rpy="-1.57 -0.000001 1.57"/>
  </joint>
  <joint name="joint_base_to_jaw_2" type="prismatic">
    <parent link="base_gripper_1"/>
    <child link="jaw_2"/>
    <axis xyz="0 -1 0"/>
    <origin xyz="0.01455 -0.0796 -0.011066" rpy="1.5708 0 0"/>
    <limit effort="1" lower="-0.01" upper="0.01" velocity="5"/>
  </joint>
  <link name="jaw_2">
    <visual>
      <origin xyz="-0.007 -0.0064 -0.0166" rpy="0 0 0"/>
      <geometry>
        <box size="0.02 0.01 0.035"/>
      </geometry>
    </visual>
    <collision>
      <origin xyz="-0.007 -0.0064 -0.0166" rpy="0 0 0"/>
      <geometry>
        <box size="0.02 0.01 0.035"/>
      </geometry>
    </collision>
  </link>
  <joint name="joint_base_to_jaw_1" type="prismatic">
    <parent link="base_gripper_1"/>
    <child link="jaw_1"/>
    <axis xyz="0 1 0"/>
    <origin xyz="0.01455 -0.0796 0.009614" rpy="1.5708 0 0"/>
    <limit effort="1" lower="-0.01" upper="0.01" velocity="5"/>
  </joint>
  <link name="jaw_1">
    <visual>
      <origin xyz="-0.007 0.0064 -0.0166" rpy="0 0 0"/>
      <geometry>
        <box size="0.02 0.01 0.035"/>
      </geometry>
    </visual>
    <collision>
      <origin xyz="-0.007 0.0064 -0.0166" rpy="0 0 0"/>
      <geometry>
        <box size="0.02 0.01 0.035"/>
      </geometry>
    </collision>
  </link>
  <link name="camera">
  </link>
  <joint name="hand_link_camera_joint" type="fixed">
    <parent link="hand_link"/>
    <child link="camera"/>
    <origin xyz="0 0 0.07" rpy="3.141593 0.000593 3.141593"/>
  </joint>
</robot>
